<!-- Cheetah Model
    The state space is populated with joints in the order that they are
    defined in this file. The actuators also operate on joints.
    State-Space (name/joint/parameter):
        - rootx     slider      position (m)
        - rootz     slider      position (m)
        - rooty     hinge       angle (rad)
        - bthigh    hinge       angle (rad)
        - bshin     hinge       angle (rad)
        - bfoot     hinge       angle (rad)
        - fthigh    hinge       angle (rad)
        - fshin     hinge       angle (rad)
        - ffoot     hinge       angle (rad)
        - rootx     slider      velocity (m/s)
        - rootz     slider      velocity (m/s)
        - rooty     hinge       angular velocity (rad/s)
        - bthigh    hinge       angular velocity (rad/s)
        - bshin     hinge       angular velocity (rad/s)
        - bfoot     hinge       angular velocity (rad/s)
        - fthigh    hinge       angular velocity (rad/s)
        - fshin     hinge       angular velocity (rad/s)
        - ffoot     hinge       angular velocity (rad/s)
    Actuators (name/actuator/parameter):
        - bthigh    hinge       torque (N m)
        - bshin     hinge       torque (N m)
        - bfoot     hinge       torque (N m)
        - fthigh    hinge       torque (N m)
        - fshin     hinge       torque (N m)
        - ffoot     hinge       torque (N m)
-->
<mujoco model="alien_cheetah">
  <compiler angle="radian" />
  <default>
    <joint armature="1" damping="1" limited="true"/>
    <geom condim="6" density="5.0" friction="1 0.5 0.5" margin="0.01" rgba="1 0 0 1"/>
    <motor ctrllimited="true" ctrlrange="-1 1"/>
  </default>
  <option timestep="0.01"/>
  <size njmax="3000" nconmax="1000"/>

  <worldbody>
     <geom name="floor" size="5 5 0.1" type="plane" condim="6"/>
    <body name="robot" pos="0 0 .6">
      <site name="robot" rgba="1 0 0 .1"/>
      <camera name="vision" pos=".125 0 .2" xyaxes="0 -1 0 .4 0 1" fovy="100"/>
      <joint armature="0" axis="1 0 0" damping="0" limited="false" name="rootx" pos="0 0 0" stiffness="0" type="slide"/>
      <joint armature="0" axis="0 0 1" damping="0" limited="false" name="rootz" pos="0 0 0" stiffness="0" type="hinge"/>
      <joint armature="0" axis="0 1 0" damping="0" limited="false" name="rooty" pos="0 0 0" stiffness="0" type="slide"/>
      <geom fromto="-.5 0 -0.1 .3 0 0" name="robot" size="0.046" type="capsule"/>
      <geom axisangle="0 1 0 .87" name="head" pos=".4 0 .1" size="0.046 .15" type="capsule"/>
      <!-- <site name='tip'  pos='.15 0 .11'/>-->
      <body name="blthigh" pos="-.5 0 -0.1" euler="0.5 0 -0.8">
        <joint axis="0 1 0" damping="6" name="blthigh" pos="0 0 0" range="-.52 1.05" stiffness="240" type="hinge"/>
        <geom axisangle="0 1 0 -3.8" name="blthigh" pos=".1 0 -.13" size="0.046 .145" type="capsule"/>
        <body name="blshin" pos=".16 0 -.25">
          <joint axis="0 1 0" damping="4.5" name="blshin" pos="0 0 0" range="-.785 .785" stiffness="180" type="hinge"/>
          <geom axisangle="0 1 0 -2.03" name="blshin" pos="-.14 0 -.07" rgba="1 0  0 1" size="0.046 .15" type="capsule"/>
          <body name="blfoot" pos="-.28 0 -.14">
            <joint axis="0 1 0" damping="3" name="blfoot" pos="0 0 0" range="-.4 .785" stiffness="120" type="hinge"/>
            <geom axisangle="0 1 0 -.27" name="blfoot" pos=".03 0 -.097" rgba="1 0  0 1" size="0.046 .094" type="capsule"/>
          </body>
        </body>
      </body>

      <body name="brthigh" pos="-.5 0 -0.1" euler="-0.5 0 0.8">
        <joint axis="0 1 0" damping="6" name="brthigh" pos="0 0 0" range="-.52 1.05" stiffness="240" type="hinge"/>
        <geom axisangle="0 1 0 -3.8" name="brthigh" pos=".1 0 -.13" size="0.046 .145" type="capsule"/>
        <body name="brshin" pos=".16 0 -.25">
          <joint axis="0 1 0" damping="4.5" name="brshin" pos="0 0 0" range="-.785 .785" stiffness="180" type="hinge"/>
          <geom axisangle="0 1 0 -2.03" name="brshin" pos="-.14 0 -.07" rgba="1 0  0 1" size="0.046 .15" type="capsule"/>
          <body name="brfoot" pos="-.28 0 -.14">
            <joint axis="0 1 0" damping="3" name="brfoot" pos="0 0 0" range="-.4 .785" stiffness="120" type="hinge"/>
            <geom axisangle="0 1 0 -.27" name="brfoot" pos=".03 0 -.097" rgba="1 0  0 1" size="0.046 .094" type="capsule"/>
          </body>
        </body>
      </body>

      <body name="fthigh" pos=".3 0 0">
        <joint axis="0 1 0" damping="4.5" name="fthigh" pos="0 0 0" range="-1 .7" stiffness="180" type="hinge"/>
        <geom axisangle="0 1 0 .52" name="fthigh" pos="-.07 0 -.12" size="0.046 .133" type="capsule"/>
        <body name="fshin" pos="-.14 0 -.24">
          <joint axis="0 1 0" damping="3" name="fshin" pos="0 0 0" range="-1.2 .87" stiffness="120" type="hinge"/>
          <geom axisangle="0 1 0 -.6" name="fshin" pos=".065 0 -.09" rgba="1 0 0 1" size="0.046 .106" type="capsule"/>
          <body name="ffoot" pos=".13 0 -.18">
            <joint axis="0 1 0" damping="1.5" name="ffoot" pos="0 0 0" range="-.5 .5" stiffness="60" type="hinge"/>
            <geom axisangle="0 1 0 -.6" name="ffoot" pos=".045 0 -.07" rgba="1 0 0 1" size="0.046 .07" type="capsule"/>
          </body>
        </body>
      </body>
    </body>
  </worldbody>
  <sensor>
        <jointpos joint="blthigh" name="jointpos_blthigh"/>
        <jointpos joint="blshin" name="jointpos_blshin"/>
        <jointpos joint="blfoot" name="jointpos_blfoot"/>
        <jointpos joint="fthigh" name="jointpos_fthigh"/>
        <jointpos joint="fshin" name="jointpos_fshin"/>
        <jointpos joint="ffoot" name="jointpos_ffoot"/>

        <jointvel joint="blthigh" name="jointvel_blthigh"/>
        <jointvel joint="blshin" name="jointvel_blshin"/>
        <jointvel joint="blfoot" name="jointvel_blfoot"/>
        <jointvel joint="fthigh" name="jointvel_fthigh"/>
        <jointvel joint="fshin" name="jointvel_fshin"/>
        <jointvel joint="ffoot" name="jointvel_ffoot"/>

        <!-- Used for observation -->
        <accelerometer site="robot" name="accelerometer"/>
        <velocimeter site="robot" name="velocimeter"/>
        <gyro site="robot" name="gyro"/>
        <magnetometer site="robot" name="magnetometer"/>

        <!-- Used for intrinsic constraints -->
        <subtreecom body="robot" name="subtreecom"/>
        <subtreelinvel body="robot" name="subtreelinvel"/>
        <subtreeangmom body="robot" name="subtreeangmom"/>
  </sensor>
  <actuator>
    <motor gear="60" joint="blthigh" name="blthigh"/>
    <motor gear="20" joint="blshin" name="blshin"/>
    <motor gear="10" joint="blfoot" name="blfoot"/>
    <motor gear="60" joint="brthigh" name="brthigh"/>
    <motor gear="20" joint="brshin" name="brshin"/>
    <motor gear="10" joint="brfoot" name="brfoot"/>
    <motor gear="60" joint="fthigh" name="fthigh"/>
    <motor gear="50" joint="fshin" name="fshin"/>
    <motor gear="50" joint="ffoot" name="ffoot"/>
  </actuator>
</mujoco>