<mujoco model="walker3d">
  <compiler angle="degree" coordinate="local" inertiafromgeom="true"/>
  <size njmax="3000" nconmax="1000"/>
  <default>
    <joint armature="1" damping="10" limited="true"/>
    <geom condim="6" density="500" friction=".7 .1 .1" rgba="1 0 0  1"/>
    <site size="0.05" type="sphere" rgba="0 0 1 1"/>
  </default>
  <option timestep="0.002"/>
  <worldbody>
    <geom name="floor" size="5 5 0.1" type="plane" condim="6"/>
    <body name="robot" pos="0 0 1.05">
      <site name="robot" rgba="1 0 0 .1"/>
      <camera name="vision" pos=".125 0 .2" xyaxes="0 -1 0 .4 0 1" fovy="100"/>
      <!-- <joint armature="0" damping="0" limited="false" margin="0.01" name="root" pos="0 0 0" type="free"/> -->
      <joint armature="0" axis="1 0 0" damping="0" limited="false" name="rootx" pos="0 0 0" stiffness="0" type="slide"/>
      <joint armature="0" axis="0 0 1" damping="0" limited="false" name="rootz" pos="0 0 0" stiffness="0" type="hinge"/>
      <joint armature="0" axis="0 1 0" damping="0" limited="false" name="rooty" pos="0 0 0" stiffness="0" type="slide"/>
      
      <geom friction="0.9" fromto="0 0.2 0 0 -0.2 0" name="robot_geom" size="0.05" type="capsule"/>
      <body name="thigh" pos="0 0.2 0">
        <joint axis="0 -1 0" name="thigh_joint" pos="0 0 0" range="-150 0" type="hinge"/>
        <geom friction="0.9" fromto="0 0 0 0 0 -0.45" name="thigh_geom" size="0.05" type="capsule"/>
        <body name="leg" pos="0 0 -0.7">
          <joint axis="0 -1 0" name="leg_joint" pos="0 0 0.25" range="-150 0" type="hinge"/>
          <geom friction="0.9" fromto="0 0 0.25 0 0 -0.25" name="leg_geom" size="0.04" type="capsule"/>
          <body name="foot" pos="0.2 0 -0.35">
            <joint axis="0 -1 0" name="foot_joint" pos="-0.2 0 0.1" range="-45 45" type="hinge"/>
            <geom friction="0.9" fromto="-0.2 0 0.1 0.0 0 0.1" name="foot_geom" size="0.06" type="capsule"/>
            <site name="foot" pos="0.0 0 0.1"/>
          </body>
        </body>
      </body>
      <!-- copied and then replace thigh->thigh_left, leg->leg_left, foot->foot_right -->
      <body name="thigh_left" pos="0 -0.2 0">
        <joint axis="0 -1 0" name="thigh_left_joint" pos="0 0 0" range="-150 0" type="hinge"/>
        <geom friction="0.9" fromto="0 0 0 0 0 -0.45" name="thigh_left_geom" size="0.05" type="capsule"/>
        <body name="leg_left" pos="0 0 -0.7">
          <joint axis="0 -1 0" name="leg_left_joint" pos="0 0 0.25" range="-150 0" type="hinge"/>
          <geom friction="0.9" fromto="0 0 0.25 0 0 -0.25" name="leg_left_geom" size="0.04" type="capsule"/>
          <body name="foot_left" pos="0.2 0 -0.35">
            <joint axis="0 -1 0" name="foot_left_joint" pos="-0.2 0 0.1" range="-45 45" type="hinge"/>
            <geom friction="1.9" fromto="-0.2 0 0.1 0.0 0 0.1" name="foot_left_geom" size="0.06" type="capsule"/>
            <site name="foot_left" pos="0.0 0 0.1"/>
          </body>
        </body>
      </body>
    </body>
  </worldbody>
  <sensor>
    <touch site="foot" name="touch_foot"/>
    <touch site="foot_left" name="touch_foot_left"/>

    <jointpos joint="thigh_joint" name="jointpos_thigh_joint"/>
    <jointpos joint="leg_joint" name="jointpos_leg_joint"/>
    <jointpos joint="foot_joint" name="jointpos_foot_joint"/>
    <jointpos joint="thigh_left_joint" name="jointpos_thigh_left_joint"/>
    <jointpos joint="leg_left_joint" name="jointpos_leg_left_joint"/>
    <jointpos joint="foot_left_joint" name="jointpos_foot_left_joint"/>

    <jointvel joint="thigh_joint" name="jointvel_thigh_joint"/>
    <jointvel joint="leg_joint" name="jointvel_leg_joint"/>
    <jointvel joint="foot_joint" name="jointvel_foot_joint"/>
    <jointvel joint="thigh_left_joint" name="jointvel_thigh_left_joint"/>
    <jointvel joint="leg_left_joint" name="jointvel_leg_left_joint"/>
    <jointvel joint="foot_left_joint" name="jointvel_foot_left_joint"/>

        <!-- Used for observation -->
        <accelerometer site="robot" name="accelerometer"/>
        <velocimeter site="robot" name="velocimeter"/>
        <gyro site="robot" name="gyro"/>
        <magnetometer site="robot" name="magnetometer"/>

        <!-- Used for intrinsic constraints -->
        <subtreecom body="robot" name="subtreecom"/>
        <subtreelinvel body="robot" name="subtreelinvel"/>
        <subtreeangmom body="robot" name="subtreeangmom"/>
  </sensor>
  <actuator>
    <motor ctrllimited="true" ctrlrange="-1.0 1.0" gear="25" joint="thigh_joint"/>
    <motor ctrllimited="true" ctrlrange="-1.0 1.0" gear="15" joint="leg_joint"/>
    <motor ctrllimited="true" ctrlrange="-1.0 1.0" gear="15" joint="foot_joint"/>
    <motor ctrllimited="true" ctrlrange="-1.0 1.0" gear="25" joint="thigh_left_joint"/>
    <motor ctrllimited="true" ctrlrange="-1.0 1.0" gear="15" joint="leg_left_joint"/>
    <motor ctrllimited="true" ctrlrange="-1.0 1.0" gear="15" joint="foot_left_joint"/>
  </actuator>
</mujoco>